{
 "cells": [
  {
   "cell_type": "code",
   "execution_count": 2,
   "metadata": {},
   "outputs": [
    {
     "name": "stderr",
     "output_type": "stream",
     "text": [
      "WARNING:root:Malformed experiment 'mlruns'. Detailed error Yaml file 'C:\\data\\repos\\handson-ml3\\mlruns\\mlruns\\meta.yaml' does not exist.\n",
      "Traceback (most recent call last):\n",
      "  File \"c:\\Users\\geert\\anaconda3\\envs\\homl3\\lib\\site-packages\\mlflow\\store\\tracking\\file_store.py\", line 328, in search_experiments\n",
      "    exp = self._get_experiment(exp_id, view_type)\n",
      "  File \"c:\\Users\\geert\\anaconda3\\envs\\homl3\\lib\\site-packages\\mlflow\\store\\tracking\\file_store.py\", line 422, in _get_experiment\n",
      "    meta = FileStore._read_yaml(experiment_dir, FileStore.META_DATA_FILE_NAME)\n",
      "  File \"c:\\Users\\geert\\anaconda3\\envs\\homl3\\lib\\site-packages\\mlflow\\store\\tracking\\file_store.py\", line 1368, in _read_yaml\n",
      "    return _read_helper(root, file_name, attempts_remaining=retries)\n",
      "  File \"c:\\Users\\geert\\anaconda3\\envs\\homl3\\lib\\site-packages\\mlflow\\store\\tracking\\file_store.py\", line 1361, in _read_helper\n",
      "    result = read_yaml(root, file_name)\n",
      "  File \"c:\\Users\\geert\\anaconda3\\envs\\homl3\\lib\\site-packages\\mlflow\\utils\\file_utils.py\", line 310, in read_yaml\n",
      "    raise MissingConfigException(f\"Yaml file '{file_path}' does not exist.\")\n",
      "mlflow.exceptions.MissingConfigException: Yaml file 'C:\\data\\repos\\handson-ml3\\mlruns\\mlruns\\meta.yaml' does not exist.\n",
      "2025/02/07 10:56:26 INFO mlflow.tracking.fluent: Autologging successfully enabled for sklearn.\n",
      "2025/02/07 10:56:26 INFO mlflow.utils.autologging_utils: Created MLflow autologging run with ID 'a98df870c9244da98c846e07a100c0f2', which will track hyperparameters, performance metrics, model artifacts, and lineage information for the current sklearn workflow\n",
      "2025/02/07 10:56:26 WARNING mlflow.utils.autologging_utils: Encountered unexpected error during sklearn autologging: When an mlflow-artifacts URI was supplied, the tracking URI must be a valid http or https URI, but it was currently set to file:///c:/data/repos/handson-ml3/mlruns. Perhaps you forgot to set the tracking URI to the running MLflow server. To set the tracking URI, use either of the following methods:\n",
      "1. Set the MLFLOW_TRACKING_URI environment variable to the desired tracking URI. `export MLFLOW_TRACKING_URI=http://localhost:5000`\n",
      "2. Set the tracking URI programmatically by calling `mlflow.set_tracking_uri`. `mlflow.set_tracking_uri('http://localhost:5000')`\n"
     ]
    }
   ],
   "source": [
    "import mlflow\n",
    "from sklearn.model_selection import train_test_split\n",
    "from sklearn.datasets import load_diabetes\n",
    "from sklearn.ensemble import RandomForestRegressor\n",
    "\n",
    "# set the experiment id\n",
    "\n",
    "mlflow.set_experiment('Geert')\n",
    "#mlflow.set_experiment(\"experiment_id=\"0\")\n",
    "\n",
    "mlflow.autolog()\n",
    "db = load_diabetes()\n",
    "\n",
    "X_train, X_test, y_train, y_test = train_test_split(db.data, db.target)\n",
    "\n",
    "# Create and train models.\n",
    "rf = RandomForestRegressor(n_estimators=100, max_depth=6, max_features=3)\n",
    "rf.fit(X_train, y_train)\n",
    "\n",
    "# Use the model to make predictions on the test dataset.\n",
    "predictions = rf.predict(X_test)"
   ]
  }
 ],
 "metadata": {
  "kernelspec": {
   "display_name": "homl3",
   "language": "python",
   "name": "python3"
  },
  "language_info": {
   "codemirror_mode": {
    "name": "ipython",
    "version": 3
   },
   "file_extension": ".py",
   "mimetype": "text/x-python",
   "name": "python",
   "nbconvert_exporter": "python",
   "pygments_lexer": "ipython3",
   "version": "3.10.16"
  }
 },
 "nbformat": 4,
 "nbformat_minor": 2
}
